# Cancellation and Timeouts

## Cancelling coroutine execution

- 일부 상황에서는 백그라운드에서 작업을 수행하고 있는 Coroutine들을 조절할 수 있어야 한다.  
  예를 들어, 사용자가 새로운 Coroutine을 만드는 기능을 호출했다가 나갔다고 해보자.  
  이 경우, 결과값이 더 이상 필요 없으며 기능의 작업도 중지시킬 수 있다.

- 이전에 봤듯이 `launch` 함수는 `Job`객체를 반환하는데, 이 객체로 명시적으로 작업 중단을 할 수 있다.

```kt
fun main() = runBlocking {
    doWorld()
}

suspend fun doWorld() = coroutineScope {
    val job = launch {
        repeat(1000) {i ->
            println("job: I'm sleeping $i...")
            delay(500L)
        }
    }
    delay(1300L) // 1.3초 delay
    println("main: I'm tired of waiting! ")
    job.cancel()  // job을 cancel한다.
    job.join()  // job을 마치길 기다린다.
    println("main: Now I can quit.")
}

/*
Output:
job: I'm sleeping 0...
job: I'm sleeping 1...
job: I'm sleeping 2...
main: I'm tired of waiting!
main: Now I can quit.
*/
```

- 우선 main에 1.3초의 delay가 걸리기에 `launch`가 수행되는데, 1.3초 후에 `job.cancel()`이 호출되며  
  `launch` 내부의 Coroutine의 작동을 중지한다. 그 후 `job.join()`을 호출하여 Coroutine이 작업을  
  마치길 기다린다. 참고로 `Job`에는 `cancel()`과 `join()`을 함께 사용할 수 있는 `cancelAndJoin()`이 있다.

---

## Cancellation is cooperative

- Coroutine의 중단 작업은 cooperative하다. Coroutine들은 중단이 가능하기 위해 cooperative해야 한다.  
  `kotlinx.coroutines` 패키지 하위의 모든 suspending function들은 *cancellable*하다.
  Coroutine에 대해 중단 요청이 오면, 해당 요청을 받는 Coroutine이 작동 중인지를 파악한다.  
  만약 중단 요청이 처리되어 해당 Coroutine이 중지되면 `CancellationException`을 발생시킨다.  
  하지만 만약 coroutine이 특정 작업을 수행중이며 중지되어 있는지에 대한 체크를 하지 않는다면 cancel될 수 없다.

```kt
fun main() = runBlocking {
    doWorld()
}

suspend fun doWorld() = coroutineScope {
    val startTime = System.currentTimeMillis()
    val job = launch(Dispatchers.Default) {
        var nextPrintTime = startTime
        var i = 0
        while(i < 5) {
            if(System.currentTimeMillis() >= nextPrintTime) {
                println("job: I'm sleeping ${i++}...")
                nextPrintTime += 500L
            }
        }
    }
    delay(1300L)
    println("main: I'm tired of waiting!")
    job.cancelAndJoin()
    println("main: Now I can quit.")
}

/*
Output:
job: I'm sleeping 0...
job: I'm sleeping 1...
job: I'm sleeping 2...
main: I'm tired of waiting!
job: I'm sleeping 3...
job: I'm sleeping 4...
main: Now I can quit.
*/
```

- 결과를 보면 `job.cancelAndJoin()`을 호출했음에도 불구하고 `doWorld()` 내부의 Coroutine의 작업이  
   cancel되지 않는 것을 볼 수 있다. 이전 코드와 다르게 cancel이 되지 않는 이유는 Coroutine의 작업을 담는  
   job의 `launch{..}` 내부에서 **해당 Coroutine이 작업을 수행 중인지 아닌지를 검사하지 않기 때문** 이다.
  > `Dispatchers.Default`의 영향도 있다.

---

## Making Computation code cancellable

- 작업을 수행중인 Coroutine에 대해서 작업을 취소할 수 있는 방법으로는 2가지가 있다.  
  하나는 주기적으로 해당 작업을 수행하는 Coroutine이 작업을 하고 있는지를 검사하는 suspending function을 만들어서  
  체킹하는 것이다.(`yield()` 사용). 다른 하나는 명시적으로 coroutine이 작업을 수행 중인지 아닌지를 검사하는 것이다.

```kt
suspend fun doWorld() = coroutineScope {
    val startTime = System.currentTimeMillis()
    val job = launch(Dispatchers.Default) {
        var nextPrintTime = startTime
        var i = 0
        while(isActive) {
            if(System.currentTimeMillis() >= nextPrintTime) {
                println("job: I'm sleeping ${i++}...")
                nextPrintTime += 500L
            }
        }
    }
    delay(1300L)
    println("main: I'm tired of waiting!")
    job.cancelAndJoin()
    println("main: Now I can quit.")
}

/*
Output:
job: I'm sleeping 0...
job: I'm sleeping 1...
job: I'm sleeping 2...
main: I'm tired of waiting!
main: Now I can quit.
*/
```

- 위 코드를 보면, 이전 코드와는 다르게 바로 Coroutine의 작업이 cancel되었다. 이는 while문의 조건문이 `isActive`로  
  바뀌었기 때문인데, 주의할 점은 `isActive`가 우리가 직접 선언한 변수가 아니라 `kotlinx.coroutines` 패키지에서  
  제공하는 것이라는 점이다. `isActive`는 해당 변수가 사용되는 coroutineScope 내의 coroutine이 작업을 수행 중이면  
  true를, 아니면 false를 반환한다.

---

## Closing resources with finally

- 작업을 중단할 수 있는 suspending function들은 작업이 중단되면 `CancellationException`을 던진다.

```kt
suspend fun doWorld() = coroutineScope {
    val job = launch {
        try {
            repeat(1000) { i ->
                println("job: I'm sleeping $i...")
                delay(500L)
            }
        } catch(exception: CancellationException) {
            println("job: I am cancelled.")
        } finally {
            println("job: I'm running finally!")
        }
    }
    delay(1300L)
    println("main: I'm tired of waiting!")
    job.cancelAndJoin()
    println("main: Now I can quit.")
}

/*
Ouptut:
job: I'm sleeping 0...
job: I'm sleeping 1...
job: I'm sleeping 2...
main: I'm tired of waiting!
job: I am cancelled.
job: I'm running finally!
main: Now I can quit.
*/
```

- `join()`과 `cancelAndJoin`은 모두 finallize action(finally에서 수행되는 작업까지, 모든 작업)이  
  수행되기를 기다리기 때문에 가장 마지막에 `job.cancelAndJoin()`이 호출된 후에 "Now I can quit."가 나온다.

---

## Run non-cancellable block

- 위 코드의 finally 절에서 suspending function을 사용하려 하면, 해당 코드 내에서 수행된 Coroutine의 작업이  
  이미 cancel된 상태이기 때문에 `CancellationException`이 발생한다. 그럼에도 불구하고, 특정 상황에서는  
  중단된 Coroutine에 대해 작업 중단을 호출해야할 때가 있는데, 이때는 해당 코드 블록을 `withContext(NonCancellable){..}`로  
  묶어주면 된다.

```kt
fun main() = runBlocking {
    doWorld()
}

suspend fun doWorld() = coroutineScope {
    val job = launch {
        try {
            repeat(1000) { i ->
                println("job: I'm sleeping $i...")
                delay(500L)
            }
        } finally {
            withContext(NonCancellable) {
                println("job: I'm running finally.")
                delay(1000L)
                println("job: And I've just delayed for 1 sec because I'm non-cancellable")
            }
        }
    }
    delay(1300L)
    println("main: I'm tired of waiting!")
    job.cancelAndJoin()
    println("main: Now I can quit.")
}

/*
Output:
job: I'm sleeping 0...
job: I'm sleeping 1...
job: I'm sleeping 2...
main: I'm tired of waiting!
job: I'm running finally.
job: And I've just delayed for 1 sec because I'm non-cancellable
main: Now I can quit.
*/
```

## Timeout

- Coroutine의 수행을 중지해야하는 가장 흔한 이유는 timeout이 났기 때문이다.  
  만약 Coroutine의 작업에 대해 레퍼런스를 두고, 해당 작업이 오래 걸려 레퍼런스를 둔 Coroutine을  
  멈추기 위해 새로운 Coroutine을 수행한다면, `withTimeout` 함수를 사용하면 된다.

```kt
fun main() = runBlocking {
    doWorld()
}

suspend fun doWorld() = coroutineScope {
    withTimeout(1300L) {
        repeat(1000) {i ->
            println("I'm sleeping $i...")
            delay(500L)
        }
    }
}

/*
Output:
I'm sleeping 0...
I'm sleeping 1...
I'm sleeping 2...
Exception in thread "main" kotlinx.coroutines.TimeoutCancellationException: Timed out waiting for 1300 ms
	at kotlinx.coroutines.TimeoutKt.TimeoutCancellationException(Timeout.kt:186)
	at kotlinx.coroutines.TimeoutCoroutine.run(Timeout.kt:156)
	at kotlinx.coroutines.EventLoopImplBase$DelayedRunnableTask.run(EventLoop.common.kt:497)
	at kotlinx.coroutines.EventLoopImplBase.processNextEvent(EventLoop.common.kt:274)
	at kotlinx.coroutines.DefaultExecutor.run(DefaultExecutor.kt:69)
	at java.lang.Thread.run(Thread.java:748)

Process finished with exit code 1
*/
```

- 위 코드에서 `withTimeout`에 의해 발생한 `TimeoutCancellationException`은 `CancellationException`의  
  자식 클래스이다. 이전에 catch문에 `CancellationException`이 잡히는 것은 봤는데, 콘솔에 찍힌 에러 로그는 보지 못했다.  
  이는 `CancellationException`이 발생하는 이유는 cancel된 Coroutine이 생기면 발생하기에 Coroutine이 작업을  
  마칠 때까지 일반적으로 발생할 수 있다고 판단하기 때문이다. 하지만, 위 예시에서는 `withTimeout`을 사용하여 해당 함수 내부의  
  Coroutine이 인자로 전달된 1.3초 내에 작업을 끝내지 못하면 timeout으로 간주한다. timeout이 났기에 예외가 발생한 것이다.

- `TimeoutCancellationException` 또한 단순한 예외이기에, 일반적인 방식으로 자원을 종료할 수 있다.  
  단지 위 코드를 try-catch로 묶어주면 된다. 만약 try-catch로 묶기 싫다면 `withTimeout` 대신  
  `withTimeoutOrNull`를 사용하면 된다. 이 함수는 `withTimeout`과 유사하지만 timeout 발생 시 예외를  
  발생시키지 않고 null을 반환한다.

```kt
fun main() = runBlocking {
    doWorld()
}

suspend fun doWorld() = coroutineScope {
    val result = withTimeoutOrNull(1300L) {
        repeat(1000) {i ->
            println("I'm sleeping $i...")
            delay(500L)
        }
    }
    print("Result is $result")
}

/*
Output:
I'm sleeping 0...
I'm sleeping 1...
I'm sleeping 2...
Result is null
*/
```

> `withTimeout()`의 반환값은 `T` 이며, `withTimeoutOrNull()`의 반환값은 `T?`이다.  
> 위 코드의 경우에는 result의 선언과 동시에 `withTimeout()`을 선언했기에 result의 타입은 `Unit`,  
> `Unit?`가 된다.

---

## Asynchronouse timeout and resources

- `withTimeout` 블록은 비동기적으로 작동한다. 만약 해당 블록 내의 코드가 작업을 하다가 timeout이 난다면, `withTimeout`은  
  그또한 timeout으로 간주한다. 따라서 만약 블록 내에서 리소스를 할당받는 작업이 있다면, 해당 리소스를 close해주거나  
  해제시켜주는 과정이 필요하다면 주의해야 한다.

- 예를 들어, 아래 코드는 close할 수 있는 클래스인 `Resource` 클래스가 있다. 이 클래스는 acquired라는 변수가 있는데, 이 변수는  
  자신이 인스턴스로 생성되었을 때 1씩 증가하고, 자신이 close되었을 때 1씩 감소한다. 이제 짧은 `withTimeout` 블록에  
  짧은 timeout을 주고, 블록 내에서 이 클래스를 사용해보자. close는 블록의 밖에서 진행해보자.

```kt
var acquired = 0

class Resource {
    init { acquired++ }  // Resource 할당 시 1씩 증가
    fun close() { acquired-- }  // Resource close시 1씩 감소
}

fun main() {
    runBlocking {
        repeat(100_100) {
            launch {
                val resource = withTimeout(60) { // 0.06초의 timeout
                    delay(51) // 0.05초 delay
                    Resource() // Resource 인스턴스 생성
                }
                resource.close()
            }
        }
        // runBlocking 블록의 외부에서
        println(acquired) // 아직 close되지 않은 Resource가 있는지 검사
    }
}
```

- 위 코드의 결과는 항상 0은 아니다. 이는 곧 리소스의 누수(leak)가 발생하고 있음을 의미한다.  
  이를 해결하기 위해서는 `runBlocking{..}`내에서 할당받는 리소스를 변수에 저장해야 한다.  
  기존에는 `withTimeout{}`의 결과값을 변수에 저장했다.

```kt
var acquired = 0

class Resource {
    init { acquired++ }
    fun print() {
        println("Do anything with resource here!")
    }
    fun close() { acquired-- }
}

fun main() {
    runBlocking {
        repeat(100_100) {
            launch {
                var resource: Resource? = null  // Resource를 할당 받기 전에 변수에 저장
                try {
                    resource = withTimeout(51) {
                        delay(51)
                        Resource() // Resource 인스턴스 생성
                    }
                    resource.print()
                } finally {
                    resource?.close()
                }
            }
        }
        // runBlocking 블록의 외부에서
        println(acquired) // 아직 close되지 않은 Resource가 있는지 검사
    }
}
```

- 위 코드는 항상 0을 출력하며, 이는 곧 리소스의 누수가 절대 발생하지 않음을 의미한다.

---

- [참고 문서](https://kotlinlang.org/docs/cancellation-and-timeouts.html)
