# Coroutine Exceptions Handling

## Exception Propagation

- Coroutine builder는 크게 두 가지로 나뉜다. `launch()`와 `actor()` 처럼 예외들을 자동으로 전파(propagate)하는 것과,  
  `async()`와 `produce()` 처럼 사용자에게 노출(expose)하는 것이 있다. 이들 builder들은 다른 coroutine의 자식 coroutine이 아니라  
  root coroutine을 만드는데, `launch()`와 `actor()`는 예외를 Java의 `Thread.uncaughtExceptionHandler`처럼 Uncaught exception 처럼  
  취급하고, `async()`와 `produce()`는 사용자들로 하여금 최종적으로 예외를 consume하도록 한다.

- `GlobalScope`에서 root coroutine을 만드는 간단한 예제를 통해 확인해보자.

```kt
@OptIn(DelicateCoroutinesApi::class)
fun main() = runBlocking {
	val job = GlobalScope.launch {
		println("Throwing exception from launch")
		throw IndexOutOfBoundException()
	}
	job.join()
	println("Joined failed job")
	val deferred = GlobalScope.async {
		println("Throwing exception from async")
		throw ArithmeticException()
	}
	try {
		deferred.await()
		println("Unreached")
	} catch(e: ArithmeticException) {
		println("Caught ArihmeticException")
	}
}

/*
Throwing exception from launch
Exception in thread "DefaultDispatcher-worker-2 @coroutine#2" java.lang.IndexOutOfBoundsException
Joined failed job
Throwing exception from async
Caught ArithmeticException
*/
```

---

## CoroutineExceptionHandler

- Uncaught exception은 기본적으로 콘솔에 예외 정보를 출력하고 마는데, 이러한 기본적인 동작을 customize할 수 있다.  
  Root coroutine의 context element인 `CoroutineExceptionHandler`은 root coroutine과 해당 root coroutine의  
  자식 coroutine들에 대한 `catch { .. }` block처럼 사용될 수 있다. `Thread.uncaughtExceptionHandler`와 비슷하다.  
  `CoroutineExceptionHandler`에 도달했다는 것은 이미 해당 예외를 발생시킨 coroutine이 종료되었음을 의미하기 때문에  
  `CoroutineExceptionHandler` 내에서는 exception recovery가 불가하다. 이 `CoroutineExceptionHandler`는 보통  
  exception을 logging하고, 특정 에러 메시지를 보내고, 애플리케이션을 종료하거나 재시작하는 등에 사용된다.

- `CoroutineExceptionHandler`는 오로지 uncaught exception들에 대해서만 호출된다. 즉, 어떠한 방식으로든 handling되지 않은  
  예외들에 의해서만 호출된다는 것이다. 자식 coroutine들은 예외가 발생하면 parent로 delegate하고, parent는 또 그의 parent로  
  delegate하고, 이렇게 root coroutine에게까지 위임하게 된다. 그러면 child coroutine scope 내에 있는 `CoroutineExceptionHandler`는  
  아무런 일도 하지 못하게 된다.(의미가 없다.) 추가적으로 `async()` builder는 모든 예외들을 catch하고 이를 `Deferred`에 담아 반환하기에  
  여기에서도 `CoroutineExceptionHandler`의 사용은 무의미하다.

```kt
val handler = CoroutineExceptionHandler { _, exception ->
	println("CoroutineExceptionHandler got $exception")
}

val job = GlobalScope.launch(handler) {
	throw AssertionError()
}

val deferred = GlobalScope.async(handler) {
	throw ArithmeticException()
}

joinAll(job, deferred)

/*
CoroutineExceptionHandler got java.lang.AssertionError
*/
```

- 위 코드로 `async()` builder 내에서 throw된 `ArithmeticException`은 `CoroutineExceptionHandler`에 의해 처리되지 않음을 볼 수 있다.

---

## Cancellation and exceptions

- Cancellation은 예외와 밀접한 연관 관계를 갖는다. Coroutine들은 내부적으로 cancellation을 위해 `CancellationException`을 사용하고,  
  모든 handler들은 이 예외를 무시한다. 이 예외는 debug를 위해 사용될 수 있고, `catch { .. }` block으로 catch될 수 있다.  
  Coroutine이 `Job.cancel()`로 cancel되면 해당 coroutine은 작업 종료되지만, parent까지 종료시키지는 않는다.

```kt
val job = launch {
	val child = launch {
		try {
			delay(Long.MAX_VALUE)
		} finally {
			println("Child is cancelled")
		}
	}
	yield()
	println("Cancelling child")
	child.canel()
	child.join()
	yield()
	println("Parent is not cancelled")
}
job.join()

/*
Cancelling child
Child is cancelled
Parent is not cancelled
*/
```

- 만약 coroutine이 `CancellationException`이 아닌 다른 예외를 발생시키게 되면, 그 coroutine은 해당 예외와 함께 부모 coroutine도  
  종료시킨다. Structured concurrency를 위해 이런 coroutine의 동작은 override가 불가하다.

- 아래 예외 코드에서 알 수 있듯이 모든 children들이 terminate되면, exception은 부모에 의해 handling된다.

```kt
val handler = CoroutineExceptionHandler { _, exception ->
	println("CoroutineExceptionHandler got $exception")
}

val job = GlboalScope.launch(handler) {
	launch {
		try {
			delay(Long.MAX_VALUE)
		} finally {
			withContext(NonCancellable) {
				println("Children are cancelled, but exception is not handled until all children terminate")
				delay(100)
				println("The first child finished its non cancallable block")
			}
		}
	}
	launch {
		delay(10)
		println("Second child throws an exception")
		throw ArithmeticException()
	}
}
job.join()

/*
Second child throws an exception
Children are cancelled, but exception is not handled until all children terminate
The first child finished its non cancallable block
CoroutineExceptionHandler got java.lang.ArithmeticException
*/
```

---

## Exceptions aggregation

- 만약 여러 개의 child roroutine들이 예외를 발생시키며 실패하면, 일반적으로는 _"첫 번째 예외가 이기는"_ 규칙, 즉 첫 번째 예외만 handling된다.  
  첫 번째 예외 이후에 발생하는 모든 예외들은 첫 번째 예외에 _attach_ 되며, suppress 처리된다.

```kt
@OptIn(DelicateCoroutinesApi::class)
fun main() = runBlocking {
	var handler = CoroutineExceptionHandler { _, exception ->
		println("CoroutineExceptionHandler got $exception with suppressed ${exception.suppressed.contentToString()}")
	}
	val job = GlobalScope.launch(handler) {
		launch {
			try {
				delay(Long.MAX_VALUE)
			} finally {
				throw ArithmeticException()
			}
		}
		launch {
			delay(100)
			throw IOException()
		}
		delay(Long.MAX_VALUE)
	}
	job.join()
}

/*
CoroutineExceptionHandler got java.io.IOException with suppressed [java.lang.ArithmeticException]
*/
```

- 반면 `CancellationException`은 투명하고, 기본적으로 unwrap된다.

```kt
val handler = CoroutineExceptionHandler { _, exception ->
	println("CoroutineExceptionHandler got $exception")
}

val job = GlobalScope.launch(handler) {
	val inner = launch {
		launch {
			launch {
				throw IOException()
			}
		}
	}
	try {
		inner.join()
	} catch(e: CancellationException) {
		println("Rethrowing CancellationException with original cause")
		throw e
	}
}
job.join()

/*
Rethrowing CancellationException with original cause
CoroutineExceptionHandler got java.io.IOException
*/
```

- 위 코드에서 첫 번째로 발생한 예외는 `IOException`이다. 하지만 try-catch block에서 `CancellationException`이 catch 되었다.  
  즉, `CancellationException`은 다른 예외들 처럼 처음 발생한 예외인 `IOException`에 attach 되고, suppress 처리되지 않는다는 뜻이다.

---

## Supervision

- Cancellation은 coroutine의 전체 hierarchy를 통해 전파된다. 하지만 때에 따라서는 방향성이 없는, 즉 전체 coroutine의 hierarchy로  
  전파되지 않는 cancellation이 필요한 경우도 있다.

- 이런 예시로 좋은 것은 UI 컴포넌트가 있고, 해당 컴포넌트의 scope 내에서 지정된 작업(job)이 있는 경우이다.  
  만약 UI의 child task중 하나가 실패하더라도, 이 UI의 모든 작업이 함께 취소되어야 할 필요는 없다.

- 또다른 예시로 여러 개의 child job을 실행시키고, 이들의 실행을 감독하는 서버 프로세스를 떠올려보자.  
  이 서버 프로세스는 실패된 child job들을 보고, 이렇게 실패한 job들만 재시작 시킬 수 있을 것이다.

### Supervision job

- 이런 목적을 위해 `SupervisorJob`이 사용될 수 있다. 일반 `Job`와 비슷하지만, cancellation이 upwards(부모 coroutine으로)로 전파되지 않고,  
  오로지 downwards(자식 coroutine으로)로 전파된다는 차이점만이 존재한다.

```kt
val supervisor = SupervisorJob()
with(CoroutineScope(coroutineContext + supervisor)) {
	val firstChild = launch(CoroutineExceptionHandler { _, _ ->
		println("The first child is failing")
		throw AssertionError("The first child is cancelled")
	})

	val secondJob = launch {
		firstChild.join()
		println("The first child is cancelled: ${firstChild.isCancelled}, but the second one is still active")
		try {
			delay(Long.MAX_VALUE)
		} finally {
			println("The second child is cancelled because the supervisor was cancelled")
		}
	}

	firstChild.join()
	println("Cancelling the supervisor")
	supervisor.cancel()
	secondChild.join()
}

/*
The first child is failing"
The first child is cancelled: true, but the second one is still active
Cancelling the supervisor
The second child is cancelled because the supervisor was cancelled
*/
```

- 위 예시 코드로 firstChild의 cancellation이 secondChild으로 전파되지 않았음을 확인할 수 있다.  
  하지만 supervisor의 cancellation은 secondChild에 전파된다.

### Supervision scope

- `coroutineScope()`을 사용해 structured concurrency를 사용하는 대신, `supervisorScope()`을 사용해  
  _scoped_ concurrency를 사용할 수 있다. `supervisorScope()`는 cancellation을 오직 하나의 방향으로만 전파하고,  
  자신이 fail할 때만 모든 children들을 cancel 시킨다. 또한 `coroutineScope()`과 마찬가지로 모든 children의 완료를 기다린다.

```kt
try {
	supervisorScope {
		val child = launch {
			try {
				println("The child is sleeping")
				delay(Long.MAX_VALUE)
			} finally {
				println("The child is cancelled")
			}
		}
		yield()
		println("Throwing an exception from the scope")
		throw AssertionError()
	}
} catch(e: AssertionError) {
	println("Caught an assertion error")
}

/*
The child is sleeping
Throwing an exception from the scope
The child is cancelled
Caught an assertion error
*/
```

#### Exceptions in supervised coroutines

- 일반 job과 supervisor job의 또다른 중요한 차이점은 exception handling이다. 모든 child는 각각의 예외를 예외 처리 메커니즘을 이용해  
  직접 처리해야 한다. 이 차이점은 child의 실패가 parent로 전파되지 않기 때문에 생겨난다. 이는 즉 `supervisorScope()` 내에서 실행된  
  coroutine들은 각각의 scope에서 `CoroutineExceptionHandler`을 마치 root coroutine처럼 사용한다는 것이다.

```kt
val handler = CoroutineExceptionHandler { _, exception ->
	println("CoroutineExceptionHandler got $exception")
}

supervisorScope {
	val child = launch(handler) {
		println("The child throws an exception")
		throw AssertionError()
	}
	println("The scope is completing")
}
println("The scope is completed")

/*
The scope is completing
The child throws an exception
CoroutineExceptionHandler got java.lang.AssertionError
The scope is completed
*/
```

---
