# 예외 처리

- 예외 처리는 코루틴의 작동 원리 중 아주 중요한 기능이다.
  잡히지 않은 예외가 발생하면 프로그램이 종료되는 것처럼 코루틴도 잡히지 않은 예외가 발생했을 때 종료된다.  
  이 방식은 전혀 새로운게 아닌데, 스레드도 이렇게 동작한다.  
  차이가 있다면 코루틴 빌더는 부모도 종료시키며, 취소된 부모는 자식들 모두를 취소시킨다는 점이다.

- 아래 예시를 보자. 코루틴이 예외를 받았을 때, 자기 자신을 취소하고 예외를 부모에게 전달시킨다.  
  (`launch()`) 부모는 자기 자신과 자식들 모두를 취소하고, 예외를 부모에게 전파한다.(`runBlocking()`)  
  `runBlocking()`은 부모가 없는 root 코루틴이기에 프로그램을 종료시킨다.

```kt
fun main(): Unit = runBlocking {
	launch {
		launch {
			delay(1000)
			throw Error("some error")
		}

		launch {
			delay(2000)
			println("Will not be printed")
		}

		launch {
			delay(500) // 예외 발생보다 빠르다
			println("Will be printed")
		}
	}

	launch {
		delay(2000)
		println("Will not be printed")
	}
}

// Will be printed
// Exception in thread "main" java.lang.Error: some error...
```

- `launch()` 코루틴을 더하는 건 아무것도 바꾸지 못한다.  
  예외는 자식에서 부모로 전파되며, 부모가 취소되면 자식도 취소되기에 쌍방으로 전파된다.  
  예외 전파가 정지되지 않으면, 계층 구조 상 모든 코루틴이 취소되게 된다.

--

## 코루틴 종료 멈추기

- 코루틴이 종료되기 전에 예외를 잡는 것은 도움이 되지만, 조금이라도 늦으면 이미 손쓸 수 없는 상황이 되어 버린다.  
  코루틴 간의 상호작용은 `Job` 을 통해서 일어나기에, 코루틴 빌더 내부에서 새로운 코루틴 빌더를 try-catch 문을  
  통해 wrapping하는 것은 전혀 도움이 안된다.

```kt
fun main(): Unit = runBlocking {
	// try-catch로 wrapping하지 말자. 무시된다.
	try {
		launch {
			delay(1000)
			throw Error("some error")
		}
	} catch (e: Throwable) { // 이 부분은 아무런 도움이 되지 않는다.
		println("Will not be printed")
	}
	launch {
		delay(2000)
		println("Will not be printed")
	}
}

// Exception in thread "main" java.lang.Error: some error...
```

### `SupervisorJob`

- 코루틴의 종료를 멈추는 가장 중요한 방법은 `SupervisorJob` 을 사용하는 것이다.  
  `SupervisorJob` 을 사용하면 자식에서 발생한 모든 예외를 무시할 수 있다.  
  일반적으로 `SupervisorJob` 은 다수의 코루틴을 시작하는 scope로 사용된다.

```kt
fun main(): Unit = runBlocking {
	val scope = CoroutineScope(SupervisorJob())
	scope.launch {
		delay(1000)
		throw Error("some error")
	}

	scope.launch {
		delay(2000)
		println("Will be printed")
	}

	delay(3000)
}

// Exception ...
// Will be printed
```

- 흔한 실수 중 하나는 아래 코드처럼 `SupervisorJob` 을 부모 코루틴의 인자로 사용하는 것이다.  
  `(1)` 에서 정의된 `launch()` 가 `SupervisorJob` 을 인자로 받는데, 이럴 경우 `SupervisorJob` 은  
  단 하나의 자식만을 가지기에 예외를 처리하는 데 아무런 도움이 되지 않는다.  
  따라서 `SupervisorJob` 을 `Job` 대신 사용하더라도 아무런 도움이 되지 않는다.

```kt
fun main(): Unit = runBlocking {
	// 이렇게 하지 말자. 자식 코루틴 하나가 있고,
	// 부모 코루틴이 없는 Job은 일반 Job과 동일하게 작동한다.
	launch(SupervisorJob()) { // (1)
		launch {
			delay(1000)
			throw Error("some error")
		}

		launch {
			delay(2000)
			println("Will not be printed")
		}
	}

	delay(3000)
}

// Exception ...
```

- 하나의 코루틴이 취소되어도 다른 코루틴이 취소되지 않는다는 점에서, 같은 `Job` 을 다수의 코루틴에서 context로 사용하는 것이 좀 더 나은 방식이다.

```kt
fun main(): Unit = runBlocking {
	val job = SupervisorJob()
	launch(job) {
		launch {
			delay(1000)
			throw Error("some error")
		}

		launch(job) {
			delay(2000)
			println("Will be printed")
		}
	}
	job.join()
}

// (1초 후)
// Exception ...
// (1초 후)
// Will be printed
```

### `supervisorScope()`

- 예외 전파를 막는 또 다른 방법은 코루틴 빌더를 `supervisorScope()` 로 wrapping하는 것이다.  
  이는 다른 코루틴에서 발생한 예외를 무시하고, 부모와의 연결을 유지한다는 점에서 아주 편리하다.

```kt
fun main(): Unit = runBlocking {
	supervisorScope {
		launch {
			delay(1000)
			throw Error("some error")
		}

		launch {
			delay(2000)
			println("Will be printed")
		}
	}

	delay(1000)
	println("Done")
}

// Exception...
// Will be printed
// (1초 후)
// Done
```

- `supervisorScope()` 는 단지 중단 함수일 뿐이며, 중단 함수 본체를 wrapping하는 데 사용된다.  
  `supervisorScope()`의 다른 기능은 이후에 더 살펴볼 것이다.  
  `supervisorScope()`를 사용하는 일반적인 방법은 서로 무관한 다수의 작업을 scope 내에서 실행하는 것이다.

```kt
suspend fun notifyAnalytics(actions: List<UserAction>) =
	supervisorScope {
		actions.forEach { action ->
			launch { notifyAnalytics(action)
			}
		}
	}
```

- 예외 전파를 막는 또 다른 방법은 `coroutineScope()` 를 사용하는 것이다.  
  이 함수는 코루틴 빌더와는 달리, 부모에 영향을 미치는 대신 try-catch를 이용해 잡을 수 있는 예외를 던진다.  
  이 두 scope 모두 이후에 살펴볼 것이다.

- `supervisorScope()` 는 `withContext(SupervisorJob())` 으로 대체될 수 없음에 유의하자. 아래 코드를 보자.

```kt
// 이렇게 하면 안된다.
suspend fun sendNotifications(notifications: List<Notification>) =
	withContext(SupervisorJob()) {
		for (noti in notifications) {
			launch { client.send(noti) }
		}
	}
```

- 위 코드는 `Job` 이 상속되지 않는 유일한 context이기에 문제가 된다.  
  코루틴은 각각 자신만의 `Job` 을 가지며, `Job` 을 다른 코루틴에 전달해 부모-자식 관계를 맺는다.  
  위 코드에서는 `SupervisorJob` 이 `withContext()` 의 부모가 된다.  
  자식 코루틴에서 예외가 발생하면 `withContext()` 코루틴으로 전달되며, `Job` 이 취소되고,  
  자식 코루틴 또한 전부 취소되며, 마지막으로 예외가 던져진다. 이는 `SupervisorJob` 을 부모로 가져도 마찬가지다.

### `await()`

- 예외 전파를 멈출 수 있는 방법을 알아봤지만, 이것만으로는 부족하다.  
  예외가 발생했을 때 `async()` 코루틴 빌더는 `launch()` 처럼 부모 코루틴을 종료하고,  
  부모와 관련있는 다른 코루틴 빌더도 종료시킨다. `SupervisorJob` 이나 `supervisorScope()` 을 사용하면  
  이런 과정이 일어나지 않는데, `await()` 를 호출하면 어떻게 될까?

```kt
class MyException : Throwable()

suspend fun main() = supervisorScope {
	val str1 = async<String> {
		delay(1000)
		throw MyException()
	}

	val str2 = async {
		delay(2000)
		"Text2"
	}

	try {
		println(str1.await())
	} catch (e: MyException) {
		println(e)
	}

	println(str2.await())
}

// MyException
// Text2
```

- 결과에서 볼 수 있듯이 코루틴이 예외로 종료되었기에 반환할 값이 없지만, `await()` 가 `MyException`을  
  던지게 되어 `"MyException"` 이 출력된다. `supervisorScope()` 가 사용되었기에 또 다른 `async()` 는 중단되지 않고 끝까지 실행된다.

---

## `CancellationException` 은 부모까지 전파되지 않는다

- 예외가 `CancellationException` 의 서브클래스라면 부모로 전파되지 않는다.  
  단지 현재 코루틴을 취소시킬 뿐이다. `CancellationException` 은 open class 이기에 다른 클래스나 객체로 확장될 수 있다.

---
