# 코틀린의 예외 처리

- 코틀린의 예외(Exception) 처리는 Java나 다른 언어의 예외 처리와 비슷하다.  
  함수는 정상적으로 종료할 수 있지만, 오류가 발생하면 예외를 던질(throw) 수 있다.  
  함수를 호출하는 쪽에서는 그 예외를 잡아 처리할 수 있다. 발생한 예외를 함수 호출단에서  
  처리(catch)하지 않으면 함수 호출 스택을 거슬러 올라가면서 예외를 처리하는 부분이  
  나올 때까지 예외를 계속해서 다시 던진다.(rethrow)

- 코틀린의 기본 예외 처리 구문은 Java와 비슷하다.  
  예외를 던지는 방법도 마찬가지다.

```kt
if(percentage !in 0..100) {
    throw IllegalArgumentException("Percentage must be between 0 and 100")
}
```

- 다른 클래스와 마찬가지로 예외 클래스의 인스턴스를 만들 때에도 new 를 붙일 필요가 없다.  
  또한 Java와 달리 코틀린의 throw는 식이므로 다른 식에 포함될 수 있다.

```kt
val percentage =
    if(number in 0..100) number
    else throw IllegalArgumentException("Percentage must be between 0 and 100")
```

---

## try, catch, finally

- Java와 마찬가지로 예외를 처리하려면 try, catch, finally 절을 함께 사용한다.

```kt
fun readNumber(reader: BufferedReader): Int? {
  try {
	  val line = reader.readLine()
	  return Integer.parseInt(line)
  } catch (e: NumberFormatException) {
	  return null
  } finally {
	  reader.close()
  }
}
```

- 위 코드와 Java 코드의 가장 큰 차이점은 throws 절이 없다는 것이다.  
  Java에서는 위 내용의 함수를 만들려면 `throws IOException`을 붙여야 한다.  
  이는 `IOException`이 **검사 예외(Checked Exception)** 이기 때문이다. Java에서는 검사 예외들을  
  명시적으로 처리해야 한다.

- 반면, **코틀린은 검사 예외와 비검사 예외(Unchecked exception)를 구별하지 않는다.** 따라서 코틀린에서는  
  함수가 던지는 예외를 지정하지 않고, 발생한 예외를 잡아내도 되고, 잡아내지 않아도 된다.  
  실제 Java 프로그래머들이 검사 예외를 사용하는 방식을 고려해 이렇게 코틀린 예외를 설계했다.  
  Java는 검사 예외 처리를 강조하지만, 프로그래머들이 의미 없이 예외를 다시 던지거나 예외를 잡되 처리하지는  
  않고 그냥 무시하는 코드를 작성하는 경우가 자주 있다.

- Java7에 등장한 try-with-resources 문은 코틀린에서 특별히 지원하지는 않는다.

---

## try를 식으로 사용

- Java와 코틀린의 중요한 차이를 하나 더 보기 위해 위의 코드를 살짝 수정해보자.

```kt
fun readNumber(reader: BufferedReader) {
  val number = try {
    Integer.parseInt(reader.readLine())
  } catch (e: NumberFormatException) {
    return
  }
  println(number)
}
```

- 위에서 볼 수 있듯이, **코틀린의 try 키워드는 if나 when과 마찬가지로 '식'이다.**  
  따라서 try의 값을 변수에 대입할 수 있다. if와 달리 try의 본문은 반드시 중괄호로  
  둘러싸야 한다. 다른 문장과 마찬가지로 try의 본문도 내부에 여러 문장이 있으면 마지막  
  식의 값이 전체 결과 값이다.

- 위 예시에서는 catch 블록 내에서 return 문을 사용한다. 따라서 예외가 발생한 경우  
  catch 블록 다음의 코드는 실행되지 않는다. 하지만 계속 진행하고 싶다면 catch 블록도  
  값을 만들어야 한다. 역시 catch 블록도 그 안의 마지막 식이 블록 전체의 값이 된다.

```kt
fun readNumber(reader: BufferedReader) {
  val number = try {
    Integer.parseInt(reader.readLine())
  } catch (e: NumberFormatException) {
    null
  }
  println(number)
}

// Client
val reader = BufferedReader(StringReader("Not a number!"))
readNumber(reader) // null
```

- try 코드 블록의 실행이 정상적으로 끝나면 그 블록의 마지막 식이 결과다. 예외가 발생하고  
  잡히면 그 예외가 잡힌 catch 블록의 값이 결과다.

---
